Workbook

Sheet Сводка
A1: Культура шитья: семантическое ядро, Челябинск
A2: Собрано 2026-10-09. Частоты: Яндекс Вордстат (Search API), последние 30 дней, все устройства. Регион: Челябинская область (11225).
A4: Показатель | B4: Значение | C4: Пояснение
A5: Фраз в ядре, всего | B5: =COUNTA('Семантическое ядро'!B2:B840) -> 839 | C5: Базовые фразы (мои маски) плюс запросы, найденные в Вордстате по маскам («Популярные» и «Похожие»)
A6: из них базовые | B6: =COUNTIF('Семантическое ядро'!F2:F840,"базовая") -> 155 | C6: Составлены перемножением: действие × объект × условия × для кого, плюс сопутствующие услуги и нецелевые для проверки минусов
A7: из них найдены в Вордстате | B7: =COUNTIF('Семантическое ядро'!F2:F840,"Вордстат*") -> 684 | C7: Реальные запросы людей, которые я не придумывал. Очищены минус-словами и от дублей
A8: С замером по Челябинской области | B8: =COUNT('Семантическое ядро'!J2:J840) -> 182 | C8: Точная частота в регионе. У остальных есть только широкая частота по России или области
A9: Фразы приоритета A | B9: =COUNTIF('Семантическое ядро'!M2:M840,"A") -> 17 | C9: Коммерческие и сопутствующие: ≥10 запросов в мес. в области или ≥300 по России. На старт рекламы и в тексты страниц
A10: Сумма точных частот, Челябинская обл. (мес.) | B10: =SUM('Семантическое ядро'!J2:J840) -> 965 | C10: Только точные частоты: они не пересекаются, и их можно складывать
A11: Отсеяно минус-словами (запросов) | B11: =COUNTA('Отсеяно минус-словами'!A2:A401) -> 400 | C11: Нецелевые запросы с широкой частотой по России ≥100, лист «Отсеяно минус-словами»
A13: Как собрано (методика Яндекс Директа и Вордстата)
A14: 1. Вопросы до сбора | C14: Что продвигаем (пошив партий для брендов и селлеров), что нет (единичные заказы физлиц), как называют клиенты (пошив, цех, производство, давальческое сырьё)
A15: 2. Маски | C15: 82 маски: от коротких общих к уточнённым, по России и по Челябинской области
A16: 3. Парсинг Вордстата | C16: По каждой маске «Популярные» и «Похожие» запросы, до 300 штук
A17: 4. Чистка | C17: Минус-слова, объединение дублей по основам слов, отсев запросов длиннее 5 слов
A18: 5. Замер региона | C18: Широкая и точная частота по Челябинской области для базовых и отобранных запросов
A19: 6. Кластеры | C19: Каждый запрос на одну страницу сайта, правила в листе «Кластеры и страницы»
A20: 7. Минус-слова и кросс-минусовка | C20: Общие минусы и минусы для широких фраз, чтобы показ шёл по самой точной группе
A22: Что учитывают Яндекс и Google
A23: Одна страница на один кластер | C23: Не две страницы под один запрос: листы «Кластеры и страницы», «Страницы SEO»
A24: Уникальные Title, Description, H1 | C24: Черновики с проверкой длины в листе «Страницы SEO»
A25: Регион | C25: Челябинск в Яндекс Бизнесе и Вордстате; для Google профиль компании. Это настройки у клиента, не часть этого файла
A26: Данные Google | C26: Не собраны: объёмы Google Keyword Planner требуют рекламного аккаунта Google Ads. Кластеры и страницы подходят и для Google, цифры частот только Яндекса
A28: Классы частотности (курс, 30 дней)
A29: ультра-НЧ: меньше 10 | C29: Почти нет трафика
A30: НЧ: 10–100 | C30: Мало трафика
A31: СЧ: 100–1 000 | C31: Основа перфоманса, отсюда конверсии
A32: ВЧ: больше 1 000 | C32: Часто без готовности купить, подключать позже
A34: Листы
A35: Семантическое ядро | C35: Все фразы, частоты, класс, приоритет, готовая фраза для Директа
A36: Кластеры и страницы | C36: Кластер → страница, суммы частот, H1
A37: Страницы SEO | C37: URL, Title, Description с проверкой длины
A38: Семантическая карта | C38: Ветки: объект, действие, условия, для кого, где, услуги
A39: Минус-слова | C39: Общий список минусов и строка для вставки
A40: Кросс-минусовка | C40: Какие минус-слова добавить широким фразам
A41: Отсеяно минус-словами | C41: Какие реальные запросы отрезали минус-словами
A42: Не по теме | C42: Запросы без слов темы (чужие города, случайные слова), в ядро не взяты
A43: Сезонность | C43: Динамика по месяцам, Челябинская область
A44: Вопросы клиенту | C44: Противоречия в брифе, которые влияют на ядро
A46: Синий шрифт: данные Вордстата (вводные). Чёрный: формулы и текст.

Sheet Семантическое ядро
A1: № | B1: Фраза | C1: Кластер | D1: Страница сайта | E1: Тип запроса | F1: Источник | G1: РФ, широкая (в мес.) | H1: РФ, точная | I1: Челябинская обл., широкая | J1: Челябинская обл., точная | K1: Класс частотности (обл.) | L1: Доля обл. от РФ | M1: Приоритет | N1: Фраза для Директа (с операторами) | O1: Примечание
A2: 1 | B2: цех по пошиву одежды | C2: 01 Швейное производство (общее) | D2: Главная / | E2: коммерческие | F2: базовая | G2: 403 | H2: 10 | I2: 0 | J2: 0 | K2: =IF(ISNUMBER(J2),IF(J2<10,"ультра-НЧ",IF(J2<100,"НЧ",IF(J2<=1000,"СЧ","ВЧ"))),IF(ISNUMBER(I2),IF(I2<10,"ультра-НЧ",IF(I2<100,"НЧ",IF(I2<=1000,"СЧ","ВЧ"))),"нет данных")) -> ультра-НЧ | L2: =IF(AND(ISNUMBER(G2),G2>0,ISNUMBER(I2)),I2/G2,"") -> 0 | M2: C | N2: цех +по пошиву одежды
A3: 2 | B3: производство одежды под заказ | C3: 01 Швейное производство (общее) | D3: Главная / | E3: коммерческие | F3: базовая | G3: 102 | H3: 1 | I3: 0 | J3: 0 | K3: =IF(ISNUMBER(J3),IF(J3<10,"ультра-НЧ",IF(J3<100,"НЧ",IF(J3<=1000,"СЧ","ВЧ"))),IF(ISNUMBER(I3),IF(I3<10,"ультра-НЧ",IF(I3<100,"НЧ",IF(I3<=1000,"СЧ","ВЧ"))),"нет данных")) -> ультра-НЧ | L3: =IF(AND(ISNUMBER(G3),G3>0,ISNUMBER(I3)),I3/G3,"") -> 0 | M3: C | N3: производство одежды +под заказ
A4: 3 | B4: контрактный пошив одежды | C4: 01 Швейное производство (общее) | D4: Главная / | E4: коммерческие | F4: базовая | G4: 72 | H4: 7 | I4: 0 | J4: 0 | K4: =IF(ISNUMBER(J4),IF(J4<10,"ультра-НЧ",IF(J4<100,"НЧ",IF(J4<=1000,"СЧ","ВЧ"))),IF(ISNUMBER(I4),IF(I4<10,"ультра-НЧ",IF(I4<100,"НЧ",IF(I4<=1000,"СЧ","ВЧ"))),"нет данных")) -> ультра-НЧ | L4: =IF(AND(ISNUMBER(G4),G4>0,ISNUMBER(I4)),I4/G4,"") -> 0 | M4: C | N4: контрактный пошив одежды
A5: 4 | B5: контрактное швейное производство | C5: 01 Швейное производство (общее) | D5: Главная / | E5: коммерческие | F5: базовая | G5: 22 | H5: 1 | I5: 0 | J5: 0 | K5: =IF(ISNUMBER(J5),IF(J5<10,"ультра-НЧ",IF(J5<100,"НЧ",IF(J5<=1000,"СЧ","ВЧ"))),IF(ISNUMBER(I5),IF(I5<10,"ультра-НЧ",IF(I5<100,"НЧ",IF(I5<=1000,"СЧ","ВЧ"))),"нет данных")) -> ультра-НЧ | L5: =IF(AND(ISNUMBER(G5),G5>0,ISNUMBER(I5)),I5/G5,"") -> 0 | M5: C | N5: контрактное швейное производство
A6: 5 | B6: пошив одежды под ключ | C6: 01 Швейное производство (общее) | D6: Главная / | E6: коммерческие | F6: базовая | G6: 21 | H6: 2 | I6: 0 | J6: 0 | K6: =IF(ISNUMBER(J6),IF(J6<10,"ультра-НЧ",IF(J6<100,"НЧ",IF(J6<=1000,"СЧ","ВЧ"))),IF(ISNUMBER(I6),IF(I6<10,"ультра-НЧ",IF(I6<100,"НЧ",IF(I6<=1000,"СЧ","ВЧ"))),"нет данных")) -> ультра-НЧ | L6: =IF(AND(ISNUMBER(G6),G6>0,ISNUMBER(I6)),I6/G6,"") -> 0 | M6: C | N6: пошив одежды +под ключ
A7: 6 | B7: швейная фабрика челябинск | C7: 01 Швейное производство (общее) | D7: Главная / | E7: коммерческие | F7: базовая | G7: 118 | H7: 19 | I7: 90 | J7: 18 | K7: =IF(ISNUMBER(J7),IF(J7<10,"ультра-НЧ",IF(J7<100,"НЧ",IF(J7<=1000,"СЧ","ВЧ"))),IF(ISNUMBER(I7),IF(I7<10,"ультра-НЧ",IF(I7<100,"НЧ",IF(I7<=1000,"СЧ","ВЧ"))),"нет данных")) -> НЧ | L7: =IF(AND(ISNUMBER(G7),G7>0,ISNUMBER(I7)),I7/G7,"") -> 0.76271186 | M7: A | N7: швейная фабрика челябинск
A8: 7 | B8: пошив одежды от производителя | C8: 01 Швейное производство (общее) | D8: Главная / | E8: коммерческие | F8: базовая | G8: 14 | H8: 0 | I8: 0 | J8: 0 | K8: =IF(ISNUMBER(J8),IF(J8<10,"ультра-НЧ",IF(J8<100,"НЧ",IF(J8<=1000,"СЧ","ВЧ"))),IF(ISNUMBER(I8),IF(I8<10,"ультра-НЧ",IF(I8<100,"НЧ",IF(I8<=1000,"СЧ","ВЧ"))),"нет данных")) -> ультра-НЧ | L8: =IF(AND(ISNUMBER(G8),G8>0,ISNUMBER(I8)),I8/G8,"") -> 0 | M8: B2C-риск | N8: пошив одежды +от производителя | O8: Без слов «оптом», «партия», «производство»: так ищут и частные лица. В Директ только с минус-словами или не брать
A9: 8 | B9: швейное производство челябинск | C9: 01 Швейное производство (общее) | D9: Главная / | E9: коммерческие | F9: базовая | H9: 12 | I9: 46 | J9: 11 | K9: =IF(ISNUMBER(J9),IF(J9<10,"ультра-НЧ",IF(J9<100,"НЧ",IF(J9<=1000,"СЧ","ВЧ"))),IF(ISNUMBER(I9),IF(I9<10,"ультра-НЧ",IF(I9<100,"НЧ",IF(I9<=1000,"СЧ","ВЧ"))),"нет данных")) -> НЧ | L9: =IF(AND(ISNUMBER(G9),G9>0,ISNUMBER(I9)),I9/G9,"") | M9: A | N9: швейное производство челябинск
A10: 9 | B10: пошив одежды челябинск | C10: 01 Швейное производство (общее) | D10: Главная / | E10: коммерческие | F10: базовая | G10: 151 | H10: 13 | I10: 111 | J10: 11 | K10: =IF(ISNUMBER(J10),IF(J10<10,"ультра-НЧ",IF(J10<100,"НЧ",IF(J10<=1000,"СЧ","ВЧ"))),IF(ISNUMBER(I10),IF(I10<10,"ультра-НЧ",IF(I10<100,"НЧ",IF(I10<=1000,"СЧ","ВЧ"))),"нет данных")) -> НЧ | L10: =IF(AND(ISNUMBER(G10),G10>0,ISNUMBER(I10)),I10/G10,"") -> 0.73509934 | M10: B2C-риск | N10: пошив одежды челябинск | O10: Без слов «оптом», «партия», «производство»: так ищут и частные лица. В Директ только с минус-словами или не брать
A11: 10 | B11: производство одежды челябинск | C11: 01 Швейное производство (общее) | D11: Главная / | E11: коммерческие | F11: базовая | G11: 51 | H11: 20 | I11: 28 | J11: 10 | K11: =IF(ISNUMBER(J11),IF(J11<10,"ультра-НЧ",IF(J11<100,"НЧ",IF(J11<=1000,"СЧ","ВЧ"))),IF(ISNUMBER(I11),IF(I11<10,"ультра-НЧ",IF(I11<100,"НЧ",IF(I11<=1000,"СЧ","ВЧ"))),"нет данных")) -> НЧ | L11: =IF(AND(ISNUMBER(G11),G11>0,ISNUMBER(I11)),I11/G11,"") -> 0.54901961 | M11: A | N11: производство одежды челябинск
A12: 11 | B12: швейный цех | C12: 01 Швейное производство (общее) | D12: Главная / | E12: коммерческие | F12: базовая | G12: 14165 | H12: 267 | I12: 263 | J12: 8 | K12: =IF(ISNUMBER(J12),IF(J12<10,"ультра-НЧ",IF(J12<100,"НЧ",IF(J12<=1000,"СЧ","ВЧ"))),IF(ISNUMBER(I12),IF(I12<10,"ультра-НЧ",IF(I12<100,"НЧ",IF(I12<=1000,"СЧ","ВЧ"))),"нет данных")) -> ультра-НЧ | L12: =IF(AND(ISNUMBER(G12),G12>0,ISNUMBER(I12)),I12/G12,"") -> 0.01856689 | M12: B | N12: швейный цех
A13: 12 | B13: швейная фабрика | C13: 01 Швейное производство (общее) | D13: Главная / | E13: коммерческие | F13: базовая | G13: 52350 | H13: 430 | I13: 1469 | J13: 8 | K13: =IF(ISNUMBER(J13),IF(J13<10,"ультра-НЧ",IF(J13<100,"НЧ",IF(J13<=1000,"СЧ","ВЧ"))),IF(ISNUMBER(I13),IF(I13<10,"ультра-НЧ",IF(I13<100,"НЧ",IF(I13<=1000,"СЧ","ВЧ"))),"нет данных")) -> ультра-НЧ | L13: =IF(AND(ISNUMBER(G13),G13>0,ISNUMBER(I13)),I13/G13,"") -> 0.028061127 | M13: A | N13: швейная фабрика
A14: 13 | B14: швейное производство | C14: 01 Швейное производство (общее) | D14: Главная / | E14: коммерческие | F14: базовая | G14: 37637 | H14: 434 | I14: 628 | J14: 7 | K14: =IF(ISNUMBER(J14),IF(J14<10,"ультра-НЧ",IF(J14<100,"НЧ",IF(J14<=1000,"СЧ","ВЧ"))),IF(ISNUMBER(I14),IF(I14<10,"ультра-НЧ",IF(I14<100,"НЧ",IF(I14<=1000,"СЧ","ВЧ"))),"нет данных")) -> ультра-НЧ | L14: =IF(AND(ISNUMBER(G14),G14>0,ISNUMBER(I14)),I14/G14,"") -> 0.016685708 | M14: A | N14: швейное производство
A15: 14 | B15: пошив одежды на заказ | C15: 01 Швейное производство (общее) | D15: Главная / | E15: коммерческие | F15: базовая | G15: 3283 | H15: 332 | I15: 57 | J15: 7 | K15: =IF(ISNUMBER(J15),IF(J15<10,"ультра-НЧ",IF(J15<100,"НЧ",IF(J15<=1000,"СЧ","ВЧ"))),IF(ISNUMBER(I15),IF(I15<10,"ультра-НЧ",IF(I15<100,"НЧ",IF(I15<=1000,"СЧ","ВЧ"))),"нет данных")) -> ультра-НЧ | L15: =IF(AND(ISNUMBER(G15),G15>0,ISNUMBER(I15)),I15/G15,"") -> 0.017362169 | M15: B2C-риск | N15: пошив одежды +на заказ | O15: Без слов «оптом», «партия», «производство»: так ищут и частные лица. В Директ только с минус-словами или не брать
A16: 15 | B16: пошив одежды на заказ челябинск | C16: 01 Швейное производство (общее) | D16: Главная / | E16: коммерческие | F16: базовая | G16: 12 | H16: 7 | I16: 10 | J16: 6 | K16: =IF(ISNUMBER(J16),IF(J16<10,"ультра-НЧ",IF(J16<100,"НЧ",IF(J16<=1000,"СЧ","ВЧ"))),IF(ISNUMBER(I16),IF(I16<10,"ультра-НЧ",IF(I16<100,"НЧ",IF(I16<=1000,"СЧ","ВЧ"))),"нет данных")) -> ультра-НЧ | L16: =IF(AND(ISNUMBER(G16),G16>0,ISNUMBER(I16)),I16/G16,"") -> 0.83333333 | M16: B2C-риск | N16: пошив одежды +на заказ челябинск | O16: Без слов «оптом», «партия», «производство»: так ищут и частные лица. В Директ только с минус-словами или не брать
A17: 16 | B17: швейный цех челябинск | C17: 01 Швейное производство (общее) | D17: Главная / | E17: коммерческие | F17: базовая | G17: 63 | H17: 4 | I17: 59 | J17: 4 | K17: =IF(ISNUMBER(J17),IF(J17<10,"ультра-НЧ",IF(J17<100,"НЧ",IF(J17<=1000,"СЧ","ВЧ"))),IF(ISNUMBER(I17),IF(I17<10,"ультра-НЧ",IF(I17<100,"НЧ",IF(I17<=1000,"СЧ","ВЧ"))),"нет данных")) -> ультра-НЧ | L17: =IF(AND(ISNUMBER(G17),G17>0,ISNUMBER(I17)),I17/G17,"") -> 0.93650794 | M17: B | N17: швейный цех челябинск
A18: 17 | B18: пошив партий одежды | C18: 01 Швейное производство (общее) | D18: Главная / | E18: коммерческие | F18: базовая | G18: 119 | H18: 4 | I18: 2 | J18: 0 | K18: =IF(ISNUMBER(J18),IF(J18<10,"ультра-НЧ",IF(J18<100,"НЧ",IF(J18<=1000,"СЧ","ВЧ"))),IF(ISNUMBER(I18),IF(I18<10,"ультра-НЧ",IF(I18<100,"НЧ",IF(I18<=1000,"СЧ","ВЧ"))),"нет данных")) -> ультра-НЧ | L18: =IF(AND(ISNUMBER(G18),G18>0,ISNUMBER(I18)),I18/G18,"") -> 0.016806723 | M18: C | N18: пошив партий одежды
A19: 18 | B19: производство одежды | C19: 01 Швейное производство (общее) | D19: Главная / | E19: коммерческие | F19: базовая | G19: 27372 | H19: 145 | I19: 430 | J19: 1 | K19: =IF(ISNUMBER(J19),IF(J19<10,"ультра-НЧ",IF(J19<100,"НЧ",IF(J19<=1000,"СЧ","ВЧ"))),IF(ISNUMBER(I19),IF(I19<10,"ультра-НЧ",IF(I19<100,"НЧ",IF(I19<=1000,"СЧ","ВЧ"))),"нет данных")) -> ультра-НЧ | L19: =IF(AND(ISNUMBER(G19),G19>0,ISNUMBER(I19)),I19/G19,"") -> 0.015709484 | M19: B | N19: производство одежды
A20: 19 | B20: пошив верхней одежды | C20: 01 Швейное производство (общее) | D20: Главная / | E20: коммерческие | F20: Вордстат, замер региона | G20: 1715 | J20: 0 | K20: =IF(ISNUMBER(J20),IF(J20<10,"ультра-НЧ",IF(J20<100,"НЧ",IF(J20<=1000,"СЧ","ВЧ"))),IF(ISNUMBER(I20),IF(I20<10,"ультра-НЧ",IF(I20<100,"НЧ",IF(I20<=1000,"СЧ","ВЧ"))),"нет данных")) -> ультра-НЧ | L20: =IF(AND(ISNUMBER(G20),G20>0,ISNUMBER(I20)),I20/G20,"") | M20: B2C-риск | N20: пошив верхней одежды | O20: Без слов «оптом», «партия», «производство»: так ищут и частные лица. В Директ только с минус-словами или не брать
A21: 20 | B21: фабрики по пошиву одежды | C21: 01 Швейное производство (общее) | D21: Главная / | E21: коммерческие | F21: Вордстат, замер региона | G21: 1311 | J21: 0 | K21: =IF(ISNUMBER(J21),IF(J21<10,"ультра-НЧ",IF(J21<100,"НЧ",IF(J21<=1000,"СЧ","ВЧ"))),IF(ISNUMBER(I21),IF(I21<10,"ультра-НЧ",IF(I21<100,"НЧ",IF(I21<=1000,"СЧ","ВЧ"))),"нет данных")) -> ультра-НЧ | L21: =IF(AND(ISNUMBER(G21),G21>0,ISNUMBER(I21)),I21/G21,"") | M21: A | N21: фабрики +по пошиву одежды
A22: 21 | B22: пошив женской одежды | C22: 01 Швейное производство (общее) | D22: Главная / | E22: коммерческие | F22: Вордстат, замер региона | G22: 1290 | J22: 0 | K22: =IF(ISNUMBER(J22),IF(J22<10,"ультра-НЧ",IF(J22<100,"НЧ",IF(J22<=1000,"СЧ","ВЧ"))),IF(ISNUMBER(I22),IF(I22<10,"ультра-НЧ",IF(I22<100,"НЧ",IF(I22<=1000,"СЧ","ВЧ"))),"нет данных")) -> ультра-НЧ | L22: =IF(AND(ISNUMBER(G22),G22>0,ISNUMBER(I22)),I22/G22,"") | M22: B2C-риск | N22: пошив женской одежды | O22: Без слов «оптом», «партия», «производство»: так ищут и частные лица. В Директ только с минус-словами или не брать
A23: 22 | B23: индивидуальный пошив одежды | C23: 01 Швейное производство (общее) | D23: Главная / | E23: коммерческие | F23: Вордстат, замер региона | G23: 1274 | J23: 0 | K23: =IF(ISNUMBER(J23),IF(J23<10,"ультра-НЧ",IF(J23<100,"НЧ",IF(J23<=1000,"СЧ","ВЧ"))),IF(ISNUMBER(I23),IF(I23<10,"ультра-НЧ",IF(I23<100,"НЧ",IF(I23<=1000,"СЧ","ВЧ"))),"нет данных")) -> ультра-НЧ | L23: =IF(AND(ISNUMBER(G23),G23>0,ISNUMBER(I23)),I23/G23,"") | M23: B2C-риск | N23: индивидуальный пошив одежды | O23: Без слов «оптом», «партия», «производство»: так ищут и частные лица. В Директ только с минус-словами или не брать
A24: 23 | B24: пошив мужской одежды | C24: 01 Швейное производство (общее) | D24: Главная / | E24: коммерческие | F24: Вордстат, замер региона | G24: 729 | J24: 0 | K24: =IF(ISNUMBER(J24),IF(J24<10,"ультра-НЧ",IF(J24<100,"НЧ",IF(J24<=1000,"СЧ","ВЧ"))),IF(ISNUMBER(I24),IF(I24<10,"ультра-НЧ",IF(I24<100,"НЧ",IF(I24<=1000,"СЧ","ВЧ"))),"нет данных")) -> ультра-НЧ | L24: =IF(AND(ISNUMBER(G24),G24>0,ISNUMBER(I24)),I24/G24,"") | M24: B2C-риск | N24: пошив мужской одежды | O24: Без слов «оптом», «партия», «производство»: так ищут и частные лица. В Директ только с минус-словами или не брать
A25: 24 | B25: пошить одежду | C25: 01 Швейное производство (общее) | D25: Главная / | E25: коммерческие | F25: Вордстат, замер региона | G25: 706 | J25: 0 | K25: =IF(ISNUMBER(J25),IF(J25<10,"ультра-НЧ",IF(J25<100,"НЧ",IF(J25<=1000,"СЧ","ВЧ"))),IF(ISNUMBER(I25),IF(I25<10,"ультра-НЧ",IF(I25<100,"НЧ",IF(I25<=1000,"СЧ","ВЧ"))),"нет данных")) -> ультра-НЧ | L25: =IF(AND(ISNUMBER(G25),G25>0,ISNUMBER(I25)),I25/G25,"") | M25: B2C-риск | N25: пошить одежду | O25: Без слов «оптом», «партия», «производство»: так ищут и частные лица. В Директ только с минус-словами или не брать
A26: 25 | B26: пошив 1 одежды | C26: 01 Швейное производство (общее) | D26: Главная / | E26: коммерческие | F26: Вордстат, замер региона | G26: 690 | J26: 0 | K26: =IF(ISNUMBER(J26),IF(J26<10,"ультра-НЧ",IF(J26<100,"НЧ",IF(J26<=1000,"СЧ","ВЧ"))),IF(ISNUMBER(I26),IF(I26<10,"ультра-НЧ",IF(I26<100,"НЧ",IF(I26<=1000,"СЧ","ВЧ"))),"нет данных")) -> ультра-НЧ | L26: =IF(AND(ISNUMBER(G26),G26>0,ISNUMBER(I26)),I26/G26,"") | M26: B2C-риск | N26: пошив 1 одежды | O26: Без слов «оптом», «партия», «производство»: так ищут и частные лица. В Директ только с минус-словами или не брать
A27: 26 | B27: пошив детских рубашек | C27: 01 Швейное производство (общее) | D27: Главная / | E27: коммерческие | F27: Вордстат, замер региона | G27: 619 | J27: 0 | K27: =IF(ISNUMBER(J27),IF(J27<10,"ультра-НЧ",IF(J27<100,"НЧ",IF(J27<=1000,"СЧ","ВЧ"))),IF(ISNUMBER(I27),IF(I27<10,"ультра-НЧ",IF(I27<100,"НЧ",IF(I27<=1000,"СЧ","ВЧ"))),"нет данных")) -> ультра-НЧ | L27: =IF(AND(ISNUMBER(G27),G27>0,ISNUMBER(I27)),I27/G27,"") | M27: B2C-риск | N27: пошив детских рубашек | O27: Без слов «оптом», «партия», «производство»: так ищут и частные лица. В Директ только с минус-словами или не брать
A28: 27 | B28: услуги по пошиву одежды | C28: 01 Швейное производство (общее) | D28: Главная / | E28: коммерческие | F28: Вордстат, замер региона | G28: 609 | J28: 0 | K28: =IF(ISNUMBER(J28),IF(J28<10,"ультра-НЧ",IF(J28<100,"НЧ",IF(J28<=1000,"СЧ","ВЧ"))),IF(ISNUMBER(I28),IF(I28<10,"ультра-НЧ",IF(I28<100,"НЧ",IF(I28<=1000,"СЧ","ВЧ"))),"нет данных")) -> ультра-НЧ | L28: =IF(AND(ISNUMBER(G28),G28>0,ISNUMBER(I28)),I28/G28,"") | M28: B2C-риск | N28: услуги +по пошиву одежды | O28: Без слов «оптом», «партия», «производство»: так ищут и частные лица. В Директ только с минус-словами или не брать
A29: 28 | B29: пошив одежды г | C29: 01 Швейное производство (общее) | D29: Главная / | E29: коммерческие | F29: Вордстат, замер региона | G29: 573 | J29: 0 | K29: =IF(ISNUMBER(J29),IF(J29<10,"ультра-НЧ",IF(J29<100,"НЧ",IF(J29<=1000,"СЧ","ВЧ"))),IF(ISNUMBER(I29),IF(I29<10,"ультра-НЧ",IF(I29<100,"НЧ",IF(I29<=1000,"СЧ","ВЧ"))),"нет данных")) -> ультра-НЧ | L29: =IF(AND(ISNUMBER(G29),G29>0,ISNUMBER(I29)),I29/G29,"") | M29: B2C-риск | N29: пошив одежды г | O29: Без слов «оптом», «партия», «производство»: так ищут и частные лица. В Директ только с минус-словами или не брать
A30: 29 | B30: материалы пошив одежды | C30: 01 Швейное производство (общее) | D30: Главная / | E30: коммерческие | F30: Вордстат, без замера региона | G30: 543 | K30: =IF(ISNUMBER(J30),IF(J30<10,"ультра-НЧ",IF(J30<100,"НЧ",IF(J30<=1000,"СЧ","ВЧ"))),IF(ISNUMBER(I30),IF(I30<10,"ультра-НЧ",IF(I30<100,"НЧ",IF(I30<=1000,"СЧ","ВЧ"))),"нет данных")) -> нет данных | L30: =IF(AND(ISNUMBER(G30),G30>0,ISNUMBER(I30)),I30/G30,"") | M30: B2C-риск | N30: материалы пошив одежды | O30: Без слов «оптом», «партия», «производство»: так ищут и частные лица. В Директ только с минус-словами или не брать
A31: 30 | B31: фирма по пошиву одежды | C31: 01 Швейное производство (общее) | D31: Главная / | E31: коммерческие | F31: Вордстат, без замера региона | G31: 527 | K31: =IF(ISNUMBER(J31),IF(J31<10,"ультра-НЧ",IF(J31<100,"НЧ",IF(J31<=1000,"СЧ","ВЧ"))),IF(ISNUMBER(I31),IF(I31<10,"ультра-НЧ",IF(I31<100,"НЧ",IF(I31<=1000,"СЧ","ВЧ"))),"нет данных")) -> нет данных | L31: =IF(AND(ISNUMBER(G31),G31>0,ISNUMBER(I31)),I31/G31,"") | M31: B2C-риск | N31: фирма +по пошиву одежды | O31: Без слов «оптом», «партия», «производство»: так ищут и частные лица. В Директ только с минус-словами или не брать
A32: 31 | B32: пошив форменной одежды | C32: 01 Швейное производство (общее) | D32: Главная / | E32: коммерческие | F32: Вордстат, без замера региона | G32: 485 | K32: =IF(ISNUMBER(J32),IF(J32<10,"ультра-НЧ",IF(J32<100,"НЧ",IF(J32<=1000,"СЧ","ВЧ"))),IF(ISNUMBER(I32),IF(I32<10,"ультра-НЧ",IF(I32<100,"НЧ",IF(I32<=1000,"СЧ","ВЧ"))),"нет данных")) -> нет данных | L32: =IF(AND(ISNUMBER(G32),G32>0,ISNUMBER(I32)),I32/G32,"") | M32: B2C-риск | N32: пошив форменной одежды | O32: Без слов «оптом», «партия», «производство»: так ищут и частные лица. В Директ только с минус-словами или не брать
A33: 32 | B33: используют пошива одежды | C33: 01 Швейное производство (общее) | D33: Главная / | E33: коммерческие | F33: Вордстат, без замера региона | G33: 475 | K33: =IF(ISNUMBER(J33),IF(J33<10,"ультра-НЧ",IF(J33<100,"НЧ",IF(J33<=1000,"СЧ","ВЧ"))),IF(ISNUMBER(I33),IF(I33<10,"ультра-НЧ",IF(I33<100,"НЧ",IF(I33<=1000,"СЧ","ВЧ"))),"нет данных")) -> нет данных | L33: =IF(AND(ISNUMBER(G33),G33>0,ISNUMBER(I33)),I33/G33,"") | M33: B2C-риск | N33: используют пошива одежды | O33: Без слов «оптом», «партия», «производство»: так ищут и частные лица. В Директ только с минус-словами или не брать
A34: 33 | B34: пошив швейное производство | C34: 01 Швейное производство (общее) | D34: Главная / | E34: коммерческие | F34: Вордстат, без замера региона | G34: 457 | K34: =IF(ISNUMBER(J34),IF(J34<10,"ультра-НЧ",IF(J34<100,"НЧ",IF(J34<=1000,"СЧ","ВЧ"))),IF(ISNUMBER(I34),IF(I34<10,"ультра-НЧ",IF(I34<100,"НЧ",IF(I34<=1000,"СЧ","ВЧ"))),"нет данных")) -> нет данных | L34: =IF(AND(ISNUMBER(G34),G34>0,ISNUMBER(I34)),I34/G34,"") | M34: A | N34: пошив швейное производство
A35: 34 | B35: пошив одежды дому | C35: 01 Швейное производство (общее) | D35: Главная / | E35: коммерческие | F35: Вордстат, без замера региона | G35: 449 | K35: =IF(ISNUMBER(J35),IF(J35<10,"ультра-НЧ",IF(J35<100,"НЧ",IF(J35<=1000,"СЧ","ВЧ"))),IF(ISNUMBER(I35),IF(I35<10,"ультра-НЧ",IF(I35<100,"НЧ",IF(I35<=1000,"СЧ","ВЧ"))),"нет данных")) -> нет данных | L35: =IF(AND(ISNUMBER(G35),G35>0,ISNUMBER(I35)),I35/G35,"") | M35: B2C-риск | N35: пошив одежды дому | O35: Без слов «оптом», «партия», «производство»: так ищут и частные лица. В Директ только с минус-словами или не брать
A36: 35 | B36: цены на пошив одежды | C36: 01 Швейное производство (общее) | D36: Главная / | E36: коммерческие | F36: Вордстат, без замера региона | G36: 430 | K36: =IF(ISNUMBER(J36),IF(J36<10,"ультра-НЧ",IF(J36<100,"НЧ",IF(J36<=1000,"СЧ","ВЧ"))),IF(ISNUMBER(I36),IF(I36<10,"ультра-НЧ",IF(I36<100,"НЧ",IF(I36<=1000,"СЧ","ВЧ"))),"нет данных")) -> нет данных | L36: =IF(AND(ISNUMBER(G36),G36>0,ISNUMBER(I36)),I36/G36,"") | M36: B2C-риск | N36: цены +на пошив одежды | O36: Без слов «оптом», «партия», «производство»: так ищут и частные лица. В Директ только с минус-словами или не брать
A37: 36 | B37: швейная фабрика цены | C37: 01 Швейное производство (общее) | D37: Главная / | E37: коммерческие | F37: Вордстат, без замера региона | G37: 415 | K37: =IF(ISNUMBER(J37),IF(J37<10,"ультра-НЧ",IF(J37<100,"НЧ",IF(J37<=1000,"СЧ","ВЧ"))),IF(ISNUMBER(I37),IF(I37<10,"ультра-НЧ",IF(I37<100,"НЧ",IF(I37<=1000,"СЧ","ВЧ"))),"нет данных")) -> нет данных | L37: =IF(AND(ISNUMBER(G37),G37>0,ISNUMBER(I37)),I37/G37,"") | M37: A | N37: швейная фабрика цены
A38: 37 | B38: пошив одежды россия | C38: 01 Швейное производство (общее) | D38: Главная / | E38: коммерческие | F38: Вордстат, без замера региона | G38: 386 | K38: =IF(ISNUMBER(J38),IF(J38<10,"ультра-НЧ",IF(J38<100,"НЧ",IF(J38<=1000,"СЧ","ВЧ"))),IF(ISNUMBER(I38),IF(I38<10,"ультра-НЧ",IF(I38<100,"НЧ",IF(I38<=1000,"СЧ","ВЧ"))),"нет данных")) -> нет данных | L38: =IF(AND(ISNUMBER(G38),G38>0,ISNUMBER(I38)),I38/G38,"") | M38: B2C-риск | N38: пошив одежды россия | O38: Без слов «оптом», «партия», «производство»: так ищут и частные лица. В Директ только с минус-словами или не брать
A39: 38 | B39: находить одежда пошив | C39: 01 Швейное производство (общее) | D39: Главная / | E39: коммерческие | F39: Вордстат, без замера региона | G39: 385 | K39: =IF(ISNUMBER(J39),IF(J39<10,"ультра-НЧ",IF(J39<100,"НЧ",IF(J39<=1000,"СЧ","ВЧ"))),IF(ISNUMBER(I39),IF(I39<10,"ультра-НЧ",IF(I39<100,"НЧ",IF(I39<=1000,"СЧ","ВЧ"))),"нет данных")) -> нет данных | L39: =IF(AND(ISNUMBER(G39),G39>0,ISNUMBER(I39)),I39/G39,"") | M39: B2C-риск | N39: находить одежда пошив | O39: Без слов «оптом», «партия», «производство»: так ищут и частные лица. В Директ только с минус-словами или не брать
A40: 39 | B40: ип пошив одежды | C40: 01 Швейное производство (общее) | D40: Главная / | E40: коммерческие | F40: Вордстат, без замера региона | G40: 382 | K40: =IF(ISNUMBER(J40),IF(J40<10,"ультра-НЧ",IF(J40<100,"НЧ",IF(J40<=1000,"СЧ","ВЧ"))),IF(ISNUMBER(I40),IF(I40<10,"ультра-НЧ",IF(I40<100,"НЧ",IF(I40<=1000,"СЧ","ВЧ"))),"нет данных")) -> нет данных | L40: =IF(AND(ISNUMBER(G40),G40>0,ISNUMBER(I40)),I40/G40,"") | M40: B2C-риск | N40: ип пошив одежды | O40: Без слов «оптом», «партия», «производство»: так ищут и частные лица. В Директ только с минус-словами или не брать
...

Sheet Кластеры и страницы
A1: Кластер | B1: Страница сайта | C1: Фраз | D1: РФ, широкая (макс. по кластеру) | E1: Челябинская обл., точная (сумма) | F1: Фраз с точной частотой | G1: Доля фраз приоритета A | H1: Фраз приоритета A | I1: H1 страницы (черновик) | J1: Минус-слова кластера (добавить к общим)
A2: 01 Швейное производство (общее) | B2: Главная / | C2: =COUNTIF('Семантическое ядро'!$C$2:$C$840,A2) -> 222 | D2: =_xlfn.MAXIFS('Семантическое ядро'!$G$2:$G$840,'Семантическое ядро'!$C$2:$C$840,A2) -> 299533 | E2: =SUMIFS('Семантическое ядро'!$J$2:$J$840,'Семантическое ядро'!$C$2:$C$840,A2) -> 118 | F2: =COUNTIFS('Семантическое ядро'!$C$2:$C$840,A2,'Семантическое ядро'!$J$2:$J$840,">=0") -> 35 | G2: =IF(C2>0,H2/C2,"") -> 0.04954955 | H2: =COUNTIFS('Семантическое ядро'!$C$2:$C$840,A2,'Семантическое ядро'!$M$2:$M$840,"A") -> 11 | I2: Швейное производство в Челябинске: пошив партий для брендов и селлеров
A3: 02 Опт / партии | B3: Услуги → Опт для маркетплейсов | C3: =COUNTIF('Семантическое ядро'!$C$2:$C$840,A3) -> 18 | D3: =_xlfn.MAXIFS('Семантическое ядро'!$G$2:$G$840,'Семантическое ядро'!$C$2:$C$840,A3) -> 685 | E3: =SUMIFS('Семантическое ядро'!$J$2:$J$840,'Семантическое ядро'!$C$2:$C$840,A3) -> 0 | F3: =COUNTIFS('Семантическое ядро'!$C$2:$C$840,A3,'Семантическое ядро'!$J$2:$J$840,">=0") -> 9 | G3: =IF(C3>0,H3/C3,"") -> 0 | H3: =COUNTIFS('Семантическое ядро'!$C$2:$C$840,A3,'Семантическое ядро'!$M$2:$M$840,"A") -> 0 | I3: Пошив одежды оптом в Челябинске от 300 единиц
A4: 03 Маркетплейсы WB / Ozon | B4: Услуги → Опт для маркетплейсов | C4: =COUNTIF('Семантическое ядро'!$C$2:$C$840,A4) -> 12 | D4: =_xlfn.MAXIFS('Семантическое ядро'!$G$2:$G$840,'Семантическое ядро'!$C$2:$C$840,A4) -> 89 | E4: =SUMIFS('Семантическое ядро'!$J$2:$J$840,'Семантическое ядро'!$C$2:$C$840,A4) -> 0 | F4: =COUNTIFS('Семантическое ядро'!$C$2:$C$840,A4,'Семантическое ядро'!$J$2:$J$840,">=0") -> 10 | G4: =IF(C4>0,H4/C4,"") -> 0 | H4: =COUNTIFS('Семантическое ядро'!$C$2:$C$840,A4,'Семантическое ядро'!$M$2:$M$840,"A") -> 0 | I4: Пошив одежды для Wildberries и Ozon: партии под ключ
A5: 04 Бренды / малые партии | B5: Услуги → Партии для брендов | C5: =COUNTIF('Семантическое ядро'!$C$2:$C$840,A5) -> 14 | D5: =_xlfn.MAXIFS('Семантическое ядро'!$G$2:$G$840,'Семантическое ядро'!$C$2:$C$840,A5) -> 177 | E5: =SUMIFS('Семантическое ядро'!$J$2:$J$840,'Семантическое ядро'!$C$2:$C$840,A5) -> 1 | F5: =COUNTIFS('Семантическое ядро'!$C$2:$C$840,A5,'Семантическое ядро'!$J$2:$J$840,">=0") -> 11 | G5: =IF(C5>0,H5/C5,"") -> 0 | H5: =COUNTIFS('Семантическое ядро'!$C$2:$C$840,A5,'Семантическое ядро'!$M$2:$M$840,"A") -> 0 | I5: Пошив одежды для брендов: малые партии и коллекции
A6: 05 Образец / экспериментальный цех | B6: Услуги → Образец за 2-3 дня | C6: =COUNTIF('Семантическое ядро'!$C$2:$C$840,A6) -> 11 | D6: =_xlfn.MAXIFS('Семантическое ядро'!$G$2:$G$840,'Семантическое ядро'!$C$2:$C$840,A6) -> 662 | E6: =SUMIFS('Семантическое ядро'!$J$2:$J$840,'Семантическое ядро'!$C$2:$C$840,A6) -> 2 | F6: =COUNTIFS('Семантическое ядро'!$C$2:$C$840,A6,'Семантическое ядро'!$J$2:$J$840,">=0") -> 9 | G6: =IF(C6>0,H6/C6,"") -> 0 | H6: =COUNTIFS('Семантическое ядро'!$C$2:$C$840,A6,'Семантическое ядро'!$M$2:$M$840,"A") -> 0 | I6: Пошив образца одежды за 2-3 дня: экспериментальный цех
A7: 06 Давальческое сырьё | B7: Услуги → Пошив из материала заказчика | C7: =COUNTIF('Семантическое ядро'!$C$2:$C$840,A7) -> 8 | D7: =_xlfn.MAXIFS('Семантическое ядро'!$G$2:$G$840,'Семантическое ядро'!$C$2:$C$840,A7) -> 126 | E7: =SUMIFS('Семантическое ядро'!$J$2:$J$840,'Семантическое ядро'!$C$2:$C$840,A7) -> 0 | F7: =COUNTIFS('Семантическое ядро'!$C$2:$C$840,A7,'Семантическое ядро'!$J$2:$J$840,">=0") -> 5 | G7: =IF(C7>0,H7/C7,"") -> 0 | H7: =COUNTIFS('Семантическое ядро'!$C$2:$C$840,A7,'Семантическое ядро'!$M$2:$M$840,"A") -> 0 | I7: Пошив из давальческого сырья в Челябинске
A8: 07 Худи / свитшоты / толстовки | B8: Изделия → Худи и свитшоты | C8: =COUNTIF('Семантическое ядро'!$C$2:$C$840,A8) -> 23 | D8: =_xlfn.MAXIFS('Семантическое ядро'!$G$2:$G$840,'Семантическое ядро'!$C$2:$C$840,A8) -> 761 | E8: =SUMIFS('Семантическое ядро'!$J$2:$J$840,'Семантическое ядро'!$C$2:$C$840,A8) -> 1 | F8: =COUNTIFS('Семантическое ядро'!$C$2:$C$840,A8,'Семантическое ядро'!$J$2:$J$840,">=0") -> 16 | G8: =IF(C8>0,H8/C8,"") -> 0 | H8: =COUNTIFS('Семантическое ядро'!$C$2:$C$840,A8,'Семантическое ядро'!$M$2:$M$840,"A") -> 0 | I8: Пошив худи, свитшотов и толстовок оптом | J8: -мужские -женские -купить -розница -авито
A9: 08 Платья / рубашки / брюки / шорты | B9: Изделия → Платья, рубашки, брюки | C9: =COUNTIF('Семантическое ядро'!$C$2:$C$840,A9) -> 247 | D9: =_xlfn.MAXIFS('Семантическое ядро'!$G$2:$G$840,'Семантическое ядро'!$C$2:$C$840,A9) -> 12793 | E9: =SUMIFS('Семантическое ядро'!$J$2:$J$840,'Семантическое ядро'!$C$2:$C$840,A9) -> 3 | F9: =COUNTIFS('Семантическое ядро'!$C$2:$C$840,A9,'Семантическое ядро'!$J$2:$J$840,">=0") -> 18 | G9: =IF(C9>0,H9/C9,"") -> 0 | H9: =COUNTIFS('Семантическое ядро'!$C$2:$C$840,A9,'Семантическое ядро'!$M$2:$M$840,"A") -> 0 | I9: Пошив платьев, рубашек, брюк и шорт партиями
A10: 09 DTF-печать | B10: Услуги → Печать DTF | C10: =COUNTIF('Семантическое ядро'!$C$2:$C$840,A10) -> 62 | D10: =_xlfn.MAXIFS('Семантическое ядро'!$G$2:$G$840,'Семантическое ядро'!$C$2:$C$840,A10) -> 9101 | E10: =SUMIFS('Семантическое ядро'!$J$2:$J$840,'Семантическое ядро'!$C$2:$C$840,A10) -> 29 | F10: =COUNTIFS('Семантическое ядро'!$C$2:$C$840,A10,'Семантическое ядро'!$J$2:$J$840,">=0") -> 7 | G10: =IF(C10>0,H10/C10,"") -> 0.032258065 | H10: =COUNTIFS('Семантическое ядро'!$C$2:$C$840,A10,'Семантическое ядро'!$M$2:$M$840,"A") -> 2 | I10: DTF-печать на одежде для вашего бренда | J10: -футболки -кружки -баннеры -стекло
A11: 10 Вышивка | B11: Услуги → Вышивка | C11: =COUNTIF('Семантическое ядро'!$C$2:$C$840,A11) -> 19 | D11: =_xlfn.MAXIFS('Семантическое ядро'!$G$2:$G$840,'Семантическое ядро'!$C$2:$C$840,A11) -> 26051 | E11: =SUMIFS('Семантическое ядро'!$J$2:$J$840,'Семантическое ядро'!$C$2:$C$840,A11) -> 135 | F11: =COUNTIFS('Семантическое ядро'!$C$2:$C$840,A11,'Семантическое ядро'!$J$2:$J$840,">=0") -> 8 | G11: =IF(C11>0,H11/C11,"") -> 0.21052632 | H11: =COUNTIFS('Семантическое ядро'!$C$2:$C$840,A11,'Семантическое ядро'!$M$2:$M$840,"A") -> 4 | I11: Вышивка на одежде: логотип на партию | J11: -кружки -сувениры -часы
A12: 11 Бирки / этикетки / составы | B12: Услуги → Бирки и упаковка | C12: =COUNTIF('Семантическое ядро'!$C$2:$C$840,A12) -> 54 | D12: =_xlfn.MAXIFS('Семантическое ядро'!$G$2:$G$840,'Семантическое ядро'!$C$2:$C$840,A12) -> 5040 | E12: =SUMIFS('Семантическое ядро'!$J$2:$J$840,'Семантическое ядро'!$C$2:$C$840,A12) -> 1 | F12: =COUNTIFS('Семантическое ядро'!$C$2:$C$840,A12,'Семантическое ядро'!$J$2:$J$840,">=0") -> 9 | G12: =IF(C12>0,H12/C12,"") -> 0 | H12: =COUNTIFS('Семантическое ядро'!$C$2:$C$840,A12,'Семантическое ядро'!$M$2:$M$840,"A") -> 0 | I12: Бирки, составники и упаковка для одежды | J12: -ценники -самоклеящиеся -принтер -этикетка-принтер
A13: 12 Лекала / конструктор / технолог | B13: Услуги → Конструкторское бюро | C13: =COUNTIF('Семантическое ядро'!$C$2:$C$840,A13) -> 31 | D13: =_xlfn.MAXIFS('Семантическое ядро'!$G$2:$G$840,'Семантическое ядро'!$C$2:$C$840,A13) -> 5951 | E13: =SUMIFS('Семантическое ядро'!$J$2:$J$840,'Семантическое ядро'!$C$2:$C$840,A13) -> 5 | F13: =COUNTIFS('Семантическое ядро'!$C$2:$C$840,A13,'Семантическое ядро'!$J$2:$J$840,">=0") -> 8 | G13: =IF(C13>0,H13/C13,"") -> 0 | H13: =COUNTIFS('Семантическое ядро'!$C$2:$C$840,A13,'Семантическое ядро'!$M$2:$M$840,"A") -> 0 | I13: Лекала, градация и технолог для вашей коллекции | J13: -автокад -скачать -программа -курс
A14: 13 Цена / расчёт | B14: Прайс с калькулятором | C14: =COUNTIF('Семантическое ядро'!$C$2:$C$840,A14) -> 53 | D14: =_xlfn.MAXIFS('Семантическое ядро'!$G$2:$G$840,'Семантическое ядро'!$C$2:$C$840,A14) -> 835 | E14: =SUMIFS('Семантическое ядро'!$J$2:$J$840,'Семантическое ядро'!$C$2:$C$840,A14) -> 1 | F14: =COUNTIFS('Семантическое ядро'!$C$2:$C$840,A14,'Семантическое ядро'!$J$2:$J$840,">=0") -> 8 | G14: =IF(C14>0,H14/C14,"") -> 0 | H14: =COUNTIFS('Семантическое ядро'!$C$2:$C$840,A14,'Семантическое ядро'!$M$2:$M$840,"A") -> 0 | I14: Стоимость пошива: рассчитайте онлайн
A15: 14 Информационные (блог) | B15: Блог / статьи | C15: =COUNTIF('Семантическое ядро'!$C$2:$C$840,A15) -> 18 | D15: =_xlfn.MAXIFS('Семантическое ядро'!$G$2:$G$840,'Семантическое ядро'!$C$2:$C$840,A15) -> 940 | E15: =SUMIFS('Семантическое ядро'!$J$2:$J$840,'Семантическое ядро'!$C$2:$C$840,A15) -> 0 | F15: =COUNTIFS('Семантическое ядро'!$C$2:$C$840,A15,'Семантическое ядро'!$J$2:$J$840,">=0") -> 7 | G15: =IF(C15>0,H15/C15,"") -> 0 | H15: =COUNTIFS('Семантическое ядро'!$C$2:$C$840,A15,'Семантическое ядро'!$M$2:$M$840,"A") -> 0 | I15: Статьи: как запустить бренд и выбрать производство
A16: 15 Конкуренты | B16: — (отдельная кампания, низкий приоритет) | C16: =COUNTIF('Семантическое ядро'!$C$2:$C$840,A16) -> 8 | D16: =_xlfn.MAXIFS('Семантическое ядро'!$G$2:$G$840,'Семантическое ядро'!$C$2:$C$840,A16) -> 9143 | E16: =SUMIFS('Семантическое ядро'!$J$2:$J$840,'Семантическое ядро'!$C$2:$C$840,A16) -> 7 | F16: =COUNTIFS('Семантическое ядро'!$C$2:$C$840,A16,'Семантическое ядро'!$J$2:$J$840,">=0") -> 6 | G16: =IF(C16>0,H16/C16,"") -> 0 | H16: =COUNTIFS('Семантическое ядро'!$C$2:$C$840,A16,'Семантическое ядро'!$M$2:$M$840,"A") -> 0 | I16: —
A17: 16 Нецелевые (проверка минус-слов) | B17: — (в минус) | C17: =COUNTIF('Семантическое ядро'!$C$2:$C$840,A17) -> 14 | D17: =_xlfn.MAXIFS('Семантическое ядро'!$G$2:$G$840,'Семантическое ядро'!$C$2:$C$840,A17) -> 577488 | E17: =SUMIFS('Семантическое ядро'!$J$2:$J$840,'Семантическое ядро'!$C$2:$C$840,A17) -> 662 | F17: =COUNTIFS('Семантическое ядро'!$C$2:$C$840,A17,'Семантическое ядро'!$J$2:$J$840,">=0") -> 14 | G17: =IF(C17>0,H17/C17,"") -> 0 | H17: =COUNTIFS('Семантическое ядро'!$C$2:$C$840,A17,'Семантическое ядро'!$M$2:$M$840,"A") -> 0 | I17: —
A18: 17 Другие города (расширение географии) | B18: Страницы городов (позже) | C18: =COUNTIF('Семантическое ядро'!$C$2:$C$840,A18) -> 25 | D18: =_xlfn.MAXIFS('Семантическое ядро'!$G$2:$G$840,'Семантическое ядро'!$C$2:$C$840,A18) -> 1471 | E18: =SUMIFS('Семантическое ядро'!$J$2:$J$840,'Семантическое ядро'!$C$2:$C$840,A18) -> 0 | F18: =COUNTIFS('Семантическое ядро'!$C$2:$C$840,A18,'Семантическое ядро'!$J$2:$J$840,">=0") -> 2 | G18: =IF(C18>0,H18/C18,"") -> 0 | H18: =COUNTIFS('Семантическое ядро'!$C$2:$C$840,A18,'Семантическое ядро'!$M$2:$M$840,"A") -> 0 | I18: —
A19: Итого | C19: =SUM(C2:C18) -> 839 | E19: =SUM(E2:E18) -> 965 | F19: =SUM(F2:F18) -> 182 | H19: =SUM(H2:H18) -> 17
A21: Сумма по региону считается по ТОЧНЫМ частотам (фраза в кавычках): они не пересекаются и складываются. Широкие частоты суммировать нельзя, поэтому для России показан максимум по кластеру.

Sheet Страницы SEO
A1: Кластер | B1: URL | C1: Title | D1: Длина Title | E1: Description | F1: Длина Description | G1: H1 | H1: Проверка (Title ≤ 70, Description ≤ 160)
A2: 01 Швейное производство (общее) | B2: / | C2: Швейное производство в Челябинске: пошив партий | Культура шитья | D2: =LEN(C2) -> 64 | E2: Контрактный пошив одежды для брендов и селлеров. Образец за 2-3 дня, опт от 300 единиц, бирки и упаковка. Отправляем по России. Рассчитайте стоимость онлайн. | F2: =LEN(E2) -> 157 | G2: Швейное производство в Челябинске: пошив партий для брендов и селлеров | H2: =IF(AND(D2<=70,F2<=160),"ок","слишком длинно") -> ок
A3: 02 Опт / партии | B3: /opt | C3: Пошив одежды оптом в Челябинске от 300 единиц | Культура шитья | D3: =LEN(C3) -> 62 | E3: Пошив партий одежды оптом: худи, свитшоты, платья, рубашки, брюки, шорты. Работаем на вашем сырье. Рассчитайте стоимость партии в калькуляторе. | F3: =LEN(E3) -> 143 | G3: Пошив одежды оптом в Челябинске от 300 единиц | H3: =IF(AND(D3<=70,F3<=160),"ок","слишком длинно") -> ок
A4: 03 Маркетплейсы WB / Ozon | B4: /marketplejsy | C4: Пошив одежды для Wildberries и Ozon | Культура шитья | D4: =LEN(C4) -> 52 | E4: Шьём партии для селлеров Wildberries и Ozon: от образца до упаковки по вашему ТЗ. Бирки, составники, отправка транспортной компанией по России. | F4: =LEN(E4) -> 143 | G4: Пошив одежды для Wildberries и Ozon: партии под ключ | H4: =IF(AND(D4<=70,F4<=160),"ок","слишком длинно") -> ок
A5: 04 Бренды / малые партии | B5: /brendam | C5: Пошив одежды для брендов: малые партии | Культура шитья | D5: =LEN(C5) -> 55 | E5: Пошив коллекций для брендов одежды: образцы за 2-3 дня, партии под вашей маркой, бирки, вышивка и DTF-печать. Челябинск, отправка по России. | F5: =LEN(E5) -> 140 | G5: Пошив одежды для брендов: малые партии и коллекции | H5: =IF(AND(D5<=70,F5<=160),"ок","слишком длинно") -> ок
A6: 05 Образец / экспериментальный цех | B6: /obrazec | C6: Пошив образца одежды за 2-3 дня | Экспериментальный цех | D6: =LEN(C6) -> 55 | E6: Экспериментальный цех: отшиваем образец любого изделия за 2-3 дня. Проверьте лекала и посадку до запуска партии. Челябинск. | F6: =LEN(E6) -> 123 | G6: Пошив образца одежды за 2-3 дня: экспериментальный цех | H6: =IF(AND(D6<=70,F6<=160),"ок","слишком длинно") -> ок
A7: 06 Давальческое сырьё | B7: /davalcheskoe | C7: Пошив из давальческого сырья в Челябинске | Культура шитья | D7: =LEN(C7) -> 58 | E7: Шьём из вашей ткани и фурнитуры: раскрой, пошив, контроль качества, упаковка. Партии для брендов и селлеров, отправка по России. | F7: =LEN(E7) -> 128 | G7: Пошив из давальческого сырья в Челябинске | H7: =IF(AND(D7<=70,F7<=160),"ок","слишком длинно") -> ок
A8: 07 Худи / свитшоты / толстовки | B8: /hudi-svitshoty | C8: Пошив худи, свитшотов и толстовок оптом | Культура шитья | D8: =LEN(C8) -> 56 | E8: Пошив худи, свитшотов и зип-худи партиями. Нанесение DTF-печати и вышивка, бирки и упаковка по вашему ТЗ. Челябинск. | F8: =LEN(E8) -> 116 | G8: Пошив худи, свитшотов и толстовок оптом | H8: =IF(AND(D8<=70,F8<=160),"ок","слишком длинно") -> ок
A9: 08 Платья / рубашки / брюки / шорты | B9: /platya-rubashki-bryuki | C9: Пошив платьев, рубашек, брюк и шорт партиями | Культура шитья | D9: =LEN(C9) -> 61 | E9: Пошив платьев, рубашек, брюк и шорт для брендов и маркетплейсов. Образец за 2-3 дня, партии от 300 единиц. Челябинск. | F9: =LEN(E9) -> 117 | G9: Пошив платьев, рубашек, брюк и шорт партиями | H9: =IF(AND(D9<=70,F9<=160),"ок","слишком длинно") -> ок
A10: 09 DTF-печать | B10: /dtf-pechat | C10: DTF-печать на одежде оптом в Челябинске | Культура шитья | D10: =LEN(C10) -> 56 | E10: Нанесение DTF-печати на изделия партиями: ваш логотип и принты на худи, свитшоты и другую одежду. Пошив и печать в одном цехе. | F10: =LEN(E10) -> 126 | G10: DTF-печать на одежде для вашего бренда | H10: =IF(AND(D10<=70,F10<=160),"ок","слишком длинно") -> ок
A11: 10 Вышивка | B11: /vyshivka | C11: Вышивка на одежде в Челябинске: логотип на партию | Культура шитья | D11: =LEN(C11) -> 66 | E11: Вышивка логотипа на ткани и готовой одежде: для партий брендов и селлеров. Пошив и вышивка в одном цехе, отправка по России. | F11: =LEN(E11) -> 124 | G11: Вышивка на одежде: логотип на партию | H11: =IF(AND(D11<=70,F11<=160),"ок","слишком длинно") -> ок
A12: 11 Бирки / этикетки / составы | B12: /birki-upakovka | C12: Бирки, составники и упаковка для одежды | Культура шитья | D12: =LEN(C12) -> 56 | E12: Изготовим бирки и составники, подготовим любую упаковку по ТЗ клиента. Пошив партии, маркировка и упаковка в одном месте. | F12: =LEN(E12) -> 121 | G12: Бирки, составники и упаковка для одежды | H12: =IF(AND(D12<=70,F12<=160),"ок","слишком длинно") -> ок
A13: 12 Лекала / конструктор / технолог | B13: /lekala-konstruktor | C13: Лекала, градация и технолог для коллекции | Культура шитья | D13: =LEN(C13) -> 58 | E13: Поможем с лекалами, градацией и технологией пошива для вашей коллекции. Отшиваем образец за 2-3 дня и запускаем партию. | F13: =LEN(E13) -> 119 | G13: Лекала, градация и технолог для вашей коллекции | H13: =IF(AND(D13<=70,F13<=160),"ок","слишком длинно") -> ок
... A15: 14 Информационные (блог) | B15: /blog | C15: Блог: как запустить бренд одежды и выбрать цех | Культура шитья | D15: =LEN(C15) -> 63 | E15: Статьи для брендов и селлеров: как отшить первую партию, как подготовить лекала и ТЗ, как выбрать швейное производство. | F15: =LEN(E15) -> 119 | G15: Статьи: как запустить бренд и выбрать производство | H15: =IF(AND(D15<=70,F15<=160),"ок","слишком длинно") -> ок
A17: Правила, которые у Яндекса и Google общие: одна страница на один кластер (не две страницы под один запрос), уникальные Title и Description, один H1 с главной фразой, адрес и телефон на сайте, регион Челябинск в Яндекс Вордстате и Яндекс Бизнесе. В тексты не заложены не подтверждённые факты (сроки, мощности, опыт): только то, что есть в брифе.

Sheet Семантическая карта
A1: Ветка | B1: Узел | C1: Слова и словоформы (для масок и операторов) | D1: Кластеры ядра | E1: Страница / куда ведёт
A2: 1. Объект | B2: Одежда и партия | C2: одежда, партия, партии, коллекция, серия, тираж | D2: 01, 02, 04 | E2: Главная, Услуги
A3: 1. Объект | B3: Образец | C3: образец, образцы, прототип, опытный образец, первый образец | D3: 05 | E3: Услуги → Образец за 2-3 дня
A4: 1. Объект | B4: Толстовочный ассортимент | C4: худи, зип худи, свитшот, толстовка, толстовки | D4: 07 | E4: Изделия → Худи и свитшоты
A5: 1. Объект | B5: Лёгкий ассортимент | C5: платье, платья, рубашка, рубашки, брюки, шорты | D5: 08 | E5: Изделия → Платья, рубашки, брюки
A6: 2. Действие | B6: Сделать | C6: пошив, пошить, сшить, отшить, шить, изготовление, производство, разработка | D6: все | E6: —
A7: 2. Действие | B7: Заказать | C7: заказать, заказ, под заказ, на заказ, нужен, найти производство | D7: 01–08 | E7: Калькулятор «Рассчитать стоимость»
A8: 3. Условия | B8: Объём | C8: оптом, мелким оптом, партиями, малыми партиями, мелкосерийное, от 100, от 300, минимальная партия | D8: 02, 04 | E8: Опт / Бренды
A9: 3. Условия | B9: Сырьё | C9: давальческое сырьё, из ткани заказчика, из материала заказчика | D9: 06 | E9: Услуги → Пошив из материала заказчика
A10: 3. Условия | B10: Формат работы | C10: под ключ, полный цикл, от производителя, контрактное | D10: 01 | E10: Главная
A11: 4. Для кого | B11: Маркетплейсы | C11: wildberries, вайлдберриз, вб, ozon, озон, маркетплейс, селлер | D11: 03 | E11: Услуги → Опт для маркетплейсов
A12: 4. Для кого | B12: Бренды | C12: бренд, своя марка, под своей маркой, стм, стартап, коллекция | D12: 04 | E12: Услуги → Партии для брендов
... A20: 10. Нецелевое (в минус) | B20: Физлица, учёба, работа, оборудование | C20: см. лист «Минус-слова» | D20: 16 | E20: —
A23: Как читать карту: фразы собираются перемножением узлов разных веток (Действие × Объект × Условия × Для кого). Пример: «пошив» × «худи» × «оптом» = «пошив худи оптом». Картинка карты: semanticheskaya-karta.svg

Sheet Минус-слова
A1: Категория | B1: Минус-слово / фраза | C1: Тип | D1: В формате Директа | E1: Зачем | F1: Для склейки
A2: Физлица, ателье, ремонт | B2: ателье | C2: слово | D2: -ателье | E2: Единичные заказы физлиц; сайт их отсеивает (бриф, п. 6) | F2: =IF(C2="слово",D2,"") -> -ателье
A3: Физлица, ателье, ремонт | B3: ремонт | C3: слово | D3: -ремонт | E3: Единичные заказы физлиц; сайт их отсеивает (бриф, п. 6) | F3: =IF(C3="слово",D3,"") -> -ремонт
A4: Физлица, ателье, ремонт | B4: подшить | C4: слово | D4: -подшить | E4: Единичные заказы физлиц; сайт их отсеивает (бриф, п. 6) | F4: =IF(C4="слово",D4,"") -> -подшить
A5: Физлица, ателье, ремонт | B5: подшив | C5: слово | D5: -подшив | E5: Единичные заказы физлиц; сайт их отсеивает (бриф, п. 6) | F5: =IF(C5="слово",D5,"") -> -подшив
A6: Физлица, ателье, ремонт | B6: укоротить | C6: слово | D6: -укоротить | E6: Единичные заказы физлиц; сайт их отсеивает (бриф, п. 6) | F6: =IF(C6="слово",D6,"") -> -укоротить
A7: Физлица, ателье, ремонт | B7: перешив | C7: слово | D7: -перешив | E7: Единичные заказы физлиц; сайт их отсеивает (бриф, п. 6) | F7: =IF(C7="слово",D7,"") -> -перешив
A8: Физлица, ателье, ремонт | B8: переделка | C8: слово | D8: -переделка | E8: Единичные заказы физлиц; сайт их отсеивает (бриф, п. 6) | F8: =IF(C8="слово",D8,"") -> -переделка
A9: Физлица, ателье, ремонт | B9: переделать | C9: слово | D9: -переделать | E9: Единичные заказы физлиц; сайт их отсеивает (бриф, п. 6) | F9: =IF(C9="слово",D9,"") -> -переделать
A10: Физлица, ателье, ремонт | B10: подгонка | C10: слово | D10: -подгонка | E10: Единичные заказы физлиц; сайт их отсеивает (бриф, п. 6) | F10: =IF(C10="слово",D10,"") -> -подгонка
A11: Физлица, ателье, ремонт | B11: на дому | C11: фраза | D11: -на дому | E11: Единичные заказы физлиц; сайт их отсеивает (бриф, п. 6) | F11: =IF(C11="слово",D11,"")
A12: Физлица, ателье, ремонт | B12: свадебное | C12: слово | D12: -свадебное | E12: Единичные заказы физлиц; сайт их отсеивает (бриф, п. 6) | F12: =IF(C12="слово",D12,"") -> -свадебное
A13: Физлица, ателье, ремонт | B13: выпускной | C13: слово | D13: -выпускной | E13: Единичные заказы физлиц; сайт их отсеивает (бриф, п. 6) | F13: =IF(C13="слово",D13,"") -> -выпускной
... A209: Минус-фразы | B209: пошив одежды своими руками | C209: фраза | D209: -пошив одежды своими руками | E209: Сделай сам | F209: =IF(C209="слово",D209,"")
A211: Общая строка минус-слов (одним словом, для вставки в кампанию)
A212: =_xlfn.TEXTJOIN(" ",TRUE(),F2:F209) -> -ателье -ремонт -подшить -подшив -укоротить -перешив -переделка -переделать -подгонка -свадебное -выпускной -вечернее -бальное -бальные -выкройка -выкройки -курсы -обучение -мастер-класс -урок -самостоятельно -схема -скачать -бесплатно -pdf -видео -реферат -пошагово -лоскутное -вакансия -вакансии -работа -зарплата -резюме -подработка -трудоустройство -швея -швеи -портной -оператор -мастер -обязанности -профессия -должностная -колледж -техникум -институт -образование -оверлок -запчасти -иглы -нитки -фурнитура -оборудование -б/у -бу -станок -станки -швейно-вышивальная -принтер -плоттер -программа -ткань -ткани -бизнес-план -франшиза -помещение -себестоимость -калькуляция -шторы -занавески -постельное -спецодежда -униформа -собак -питомцев -игрушки -куклы -обувь -сумки -рюкзаки -чехлы -подушки -платки -госномеров -номеров -купить -интернет-магазин -магазин -авито -секонд -ломбард -отзывы -фото -картинки -реферат -википедия -это -означает -название -называется -классификация -история -курсовая -презентация -пример -примеры -виды -отличается -отличие -отличия -расшифровка -значение -обозначение -обозначения -символы -чей -чье -чья -кроссворд -гта -игра -школа -академия -кто -какая -какой -какое -официальный -официальные -сайт -сайты -рядом -контакты -телефон -адрес -знаки -знак -значки -стирка -стирки -стирку -температура -температуры -оквэд -деятельность -технология -технологии -последовательность -варианты -упаковщик -упаковщики -упаковщиков -самозанятый -самой -сама -чем -ооо -иванова -одноклассники
A213: Приоритеты Директа: ключевая фраза важнее минус-слова (при полном совпадении показ будет), минус-фраза важнее автотаргетинга. Минус-слова ставятся на кампанию, минус-фразы на кампанию или группу (конспект курса, 12.4).

Sheet Кросс-минусовка
A1: Фраза-получатель | B1: Её кластер | C1: Минус-слова к ней | D1: Из-за каких более узких фраз других кластеров
A2: швейный цех | B2: 01 Швейное производство (общее) | C2: -оптом -цена -сколько -стоит -пошив | D2: швейный цех оптом; швейный цех цена; сколько стоит швейный цех; швейный цех пошив
A3: швейная фабрика | B3: 01 Швейное производство (общее) | C3: -пошив -заказы | D3: швейная фабрика пошив; швейная фабрика заказы
A4: швейное производство | B4: 01 Швейное производство (общее) | C4: -wildberries -давальческое -сырье -лекала -стоимость -сколько -стоит -как -выбрать | D4: швейное производство для wildberries; давальческое сырье швейное производство; швейное производство давальческое сырье; лекала швейного производства; стоимость швейного производства; сколько стоит швейное производство
A5: производство одежды | B5: 01 Швейное производство (общее) | C5: -оптом -партии -wildberries -маркетплейсов -брендов -мелкосерийное -стартапа -ключ -бренда -своего -вашего -лекал -лекала -стоимость -как -найти | D5: производство одежды оптом; производство партии одежды; производство одежды для wildberries; производство одежды для маркетплейсов; производство одежды для брендов; мелкосерийное производство одежды
A6: пошив одежды оптом | B6: 02 Опт / партии | C6: -стоимость | D6: стоимость пошива одежды оптом
A7: печать дтф | B7: 09 DTF-печать | C7: -сколько -стоит -цена -стоимость -как -делать -снять | D7: сколько стоит дтф печать; дтф печать цена; стоимость дтф печати; как делать дтф печать; как снять дтф печать
A8: вышивка на одежде | B8: 10 Вышивка | C8: -нанесение -стоимость -цена -сколько -стоит | D8: нанесение вышивки на одежду; стоимость вышивки на одежде; вышивка на одежде цена; сколько стоит вышивка на одежде
A9: бирки для одежды | B9: 11 Бирки / этикетки / составы | C9: -озон -как -сделать | D9: озон бирки для одежды; как сделать бирки для одежды
A10: конструктор одежды | B10: 12 Лекала / конструктор / технолог | C10: -пошив -сколько -зарабатывает | D10: конструирование пошив одежды; сколько зарабатывает конструктор одежды
A11: градация лекал | B11: 12 Лекала / конструктор / технолог | C11: -как -делать | D11: как делать градацию лекал
A13: Правило: широкая фраза получает минус-слова из более узких фраз других групп, чтобы запрос показывался по самой точной группе. Внутри одной группы кросс-минусовка в Директе работает автоматически; между группами можно не делать, если в кампании включена приоритизация «По фразе, наиболее близкой к запросу».

Sheet Сезонность
A1: Месяц | B1: швейное производство | C1: пошив одежды на заказ | D1: производство одежды | E1: пошив одежды оптом | F1: пошив одежды для wildberries | G1: пошив одежды для брендов | H1: пошив образцов одежды | I1: пошив худи оптом | J1: пошив свитшотов оптом | K1: пошив платьев оптом | L1: пошив рубашек оптом | M1: пошив брюк оптом | N1: пошив шорт оптом | O1: Сумма | P1: Индекс к среднему
A2: 2024-10 | B2: 992 | C2: 95 | D2: 1024 | E2: 22 | F2: 0 | G2: 2 | H2: 3 | I2: 0 | J2: 0 | K2: 0 | L2: 0 | M2: 0 | N2: 0 | O2: =SUM(B2:N2) -> 2138 | P2: =O2/AVERAGE($O$2:$O$25) -> 1.3775034
A3: 2024-11 | B3: 888 | C3: 112 | D3: 685 | E3: 21 | F3: 0 | G3: 6 | H3: 13 | I3: 0 | J3: 0 | K3: 0 | L3: 0 | M3: 0 | N3: 0 | O3: =SUM(B3:N3) -> 1725 | P3: =O3/AVERAGE($O$2:$O$25) -> 1.1114094
A4: 2024-12 | B4: 885 | C4: 84 | D4: 623 | E4: 6 | F4: 0 | G4: 1 | H4: 3 | I4: 0 | J4: 2 | K4: 0 | L4: 0 | M4: 0 | N4: 0 | O4: =SUM(B4:N4) -> 1604 | P4: =O4/AVERAGE($O$2:$O$25) -> 1.0334497
A5: 2025-01 | B5: 938 | C5: 82 | D5: 925 | E5: 19 | F5: 0 | G5: 2 | H5: 4 | I5: 1 | J5: 0 | K5: 0 | L5: 0 | M5: 0 | N5: 0 | O5: =SUM(B5:N5) -> 1971 | P5: =O5/AVERAGE($O$2:$O$25) -> 1.269906
A6: 2025-02 | B6: 1158 | C6: 102 | D6: 952 | E6: 29 | F6: 0 | G6: 2 | H6: 17 | I6: 0 | J6: 0 | K6: 2 | L6: 0 | M6: 0 | N6: 0 | O6: =SUM(B6:N6) -> 2262 | P6: =O6/AVERAGE($O$2:$O$25) -> 1.457396
A7: 2025-03 | B7: 1191 | C7: 123 | D7: 766 | E7: 24 | F7: 0 | G7: 2 | H7: 4 | I7: 0 | J7: 0 | K7: 2 | L7: 0 | M7: 0 | N7: 0 | O7: =SUM(B7:N7) -> 2112 | P7: =O7/AVERAGE($O$2:$O$25) -> 1.3607517
A8: 2025-04 | B8: 899 | C8: 113 | D8: 693 | E8: 20 | F8: 0 | G8: 0 | H8: 3 | I8: 1 | J8: 0 | K8: 0 | L8: 1 | M8: 0 | N8: 0 | O8: =SUM(B8:N8) -> 1730 | P8: =O8/AVERAGE($O$2:$O$25) -> 1.1146309
A9: 2025-05 | B9: 762 | C9: 74 | D9: 650 | E9: 9 | F9: 0 | G9: 0 | H9: 3 | I9: 0 | J9: 0 | K9: 0 | L9: 0 | M9: 0 | N9: 0 | O9: =SUM(B9:N9) -> 1498 | P9: =O9/AVERAGE($O$2:$O$25) -> 0.96515436
A10: 2025-06 | B10: 796 | C10: 103 | D10: 447 | E10: 28 | F10: 0 | G10: 8 | H10: 2 | I10: 0 | J10: 0 | K10: 1 | L10: 0 | M10: 0 | N10: 0 | O10: =SUM(B10:N10) -> 1385 | P10: =O10/AVERAGE($O$2:$O$25) -> 0.89234899
A11: 2025-07 | B11: 583 | C11: 56 | D11: 339 | E11: 5 | F11: 0 | G11: 0 | H11: 2 | I11: 0 | J11: 0 | K11: 0 | L11: 1 | M11: 0 | N11: 0 | O11: =SUM(B11:N11) -> 986 | P11: =O11/AVERAGE($O$2:$O$25) -> 0.63527517
A12: 2025-08 | B12: 526 | C12: 71 | D12: 392 | E12: 15 | F12: 0 | G12: 2 | H12: 5 | I12: 0 | J12: 0 | K12: 0 | L12: 0 | M12: 0 | N12: 0 | O12: =SUM(B12:N12) -> 1011 | P12: =O12/AVERAGE($O$2:$O$25) -> 0.65138255
A13: 2025-09 | B13: 885 | C13: 93 | D13: 512 | E13: 15 | F13: 0 | G13: 0 | H13: 1 | I13: 0 | J13: 0 | K13: 0 | L13: 0 | M13: 0 | N13: 0 | O13: =SUM(B13:N13) -> 1506 | P13: =O13/AVERAGE($O$2:$O$25) -> 0.97030872
... A25: 2026-09 | B25: 628 | C25: 48 | D25: 486 | E25: 6 | F25: 2 | G25: 4 | H25: 1 | I25: 0 | J25: 0 | K25: 0 | L25: 0 | M25: 0 | N25: 0 | O25: =SUM(B25:N25) -> 1175 | P25: =O25/AVERAGE($O$2:$O$25) -> 0.75704698
A27: Челябинская область, широкая частота по месяцам. Индекс > 1,2 = высокий сезон, < 0,8 = спад. Для запуска рекламы смотреть месяцы перед пиком.

Sheet Вопросы клиенту
A1: № | B1: Вопрос | C1: Почему важно для семантики | D1: Что поменяется
A2: 1 | B2: Какая минимальная партия? В брифе три цифры: «от 300» (п. 2), «от 100» (п. 10), у брендов заказы «бывает 10» (п. 7). | C2: От цифры зависят фразы «от 100 штук / от 300 штук», объявления и калькулятор | D2: Ядро кластеров 02 и 04, тексты объявлений, порог калькулятора
A3: 2 | B3: «Под ключ» (конструктор, технолог, ОТК, п. 10) и «работаем на давальческом сырье» (п. 2): ткань и фурнитуру покупаете вы или клиент? | C3: От ответа зависят и фразы «под ключ», и минус-слова про ткань | D3: Кластеры 01 и 06, минус «ткань оптом»
A4: 3 | B4: Шьёте ли спецодежду, униформу, детскую одежду, футболки, костюмы, трикотаж? | C4: В брифе их нет. Это часть рынка, которую мы пока не берём и поставили в минусы | D4: Лист «Минус-слова», новые кластеры
A5: 4 | B5: Какое название использовать? В брифе «Культура шитья», в соцсетях «24poshiv7» и «poshiv24_7», домен aksenovasew.ru. | C5: Брендовые запросы собираются по названию; три названия дробят узнаваемость | D5: Брендовая кампания, Яндекс Бизнес, метатеги
A6: 5 | B6: Работаете ли с заказчиками из других регионов постоянно (доставка ТК)? Какие города приоритетны? | C6: Бизнес в Челябинске, а клиенты по всей России. Региональные частоты показывают только местный спрос | D6: Гео-кампании по Екатеринбургу, Москве и др.
A7: 6 | B7: Нужно ли привлекать фразы «X оптом от производителя»? | C7: Их вводят оптовики, которым нужна готовая вещь, а не пошив | D7: Кластеры 07, 08, приоритет «Проверка»

Sheet Отсеяно минус-словами
A1: Запрос из Вордстата | B1: РФ, широкая | C1: Сработавшее минус-слово
A2: ателье | B2: 645588 | C2: ателье
A3: швея | B3: 159918 | C3: швея
A4: магазин спецодежды | B4: 65032 | C4: спецодежда
A5: комбинезоны купить | B5: 55274 | C5: купить
A6: кофта купить | B6: 51706 | C6: купить
A7: пиджаки купить | B7: 49262 | C7: купить
A8: спецодежда купить | B8: 36013 | C8: спецодежда
A9: ателье одежды | B9: 27326 | C9: ателье
A10: выкройка брюк | B10: 26681 | C10: выкройка
A11: ткани оптом | B11: 26546 | C11: ткани оптом
A12: швея вакансии | B12: 25465 | C12: вакансия
A13: курсы шитья | B13: 21865 | C13: курсы
... A401: швейный цех отзывы | B401: 135 | C401: отзывы

Sheet Не по теме
A1: Запрос из Вордстата | B1: РФ, широкая | C1: Обл., точная | D1: Почему отсеян
A2: изготовление | B2: 2161535 | C2: 46 | D2: нет слов темы
A3: кофта | B3: 1284212 | C3: 248 | D3: нет слов темы
A4: наряд | B4: 890010 | C4: 38 | D4: нет слов темы
A5: кто производитель | B5: 788389 | C5: 15 | D5: кто
A6: комбинат | B6: 507178 | C6: 18 | D6: нет слов темы
A7: промысел | B7: 405465 | C7: 56 | D7: нет слов темы
A8: толстовка | B8: 374489 | C8: 124 | D8: нет признака услуги или заказа
A9: контракт на сво | B9: 352532 | C9: 381 | D9: нет слов темы
A10: clothing | B10: 272110 | C10: 62 | D10: нет слов темы
A11: jacket | B11: 199884 | C11: 28 | D11: нет слов темы
A12: вышивание | B12: 139825 | C12: 4 | D12: нет признака услуги или заказа
A13: эксперимент это | B13: 111978 | C13: 80 | D13: это
... A392: швейные предприятия производства | B392: 562 | C392: 0 | D392: нет признака услуги или заказа
A393: швейная фабрика 4 | B393: 561 | D393: нет признака услуги или заказа
A394: ярославская швейная фабрика | B394: 559 | D394: нет признака услуги или заказа
A395: футболки оптом от производителя | B395: 559 | D395: нет слов темы
A396: компания производства одежды | B396: 558 | D396: нет признака услуги или заказа
A397: как одеть погоны на рубашку | B397: 558 | D397: нет признака услуги или заказа
A398: одежда продажа производство | B398: 552 | D398: нет признака услуги или заказа
A399: производство промышленных швейных машин | B399: 550 | D399: нет признака услуги или заказа
A400: вышивка на одежде спб | B400: 540 | D400: нет признака услуги или заказа
A401: производство специальной одежды | B401: 537 | D401: нет признака услуги или заказа
A402: ерд одежда | B402: 536 | D402: нет признака услуги или заказа
A403: frht одежда | B403: 533 | D403: нет признака услуги или заказа
A404: тверская швейная фабрика | B404: 532 | D404: нет признака услуги или заказа
... A501: материалы для производства одежды | B501: 301 | D501: нет признака услуги или заказа
